Workbook

Sheet FORMATO DE CAPACITACIONES 2026
A2: MINISTERIO DE AGRICULTURA GANADERÍA Y ALIMENTACIÓN -MAGA-
A3: DIRECCIÓN DE COORDINACIÓN REGIONAL Y EXTENSIÓN RURAL -DICORER-
A4: FORMACIÓN Y CAPACITACIÓN PARA EL DESARROLLO RURAL
A5: INFORME MENSUAL DE TALLERES O EVENTOS DE CAPACITACIÓN A NIVEL MUNICIPAL/DEPARTAMENTAL AÑO 2026
E6: (1) Mes:
A8: (3) No. | B8: (4) Nombre del evento | C8: (5) Fecha de realización | D8: (6) Comunidad, Aldea/ Municipio | E8: (7) Duración del evento (horas) | F8: (8) Nombre del Promotor | G8: (9) Número de teléfono del promotor | H8: (10) Nombre del Capacitador | I8: (11) Orientación de la capacitación (Marcar con una X) | Q8: (12) Número de Promotores | S8: (13) Otros participantes | U8: (14) Total participantes | W8: (15) Institución con quien coordina | X8: (16) Costo total | Y8: (17) Medios de Verificación (Marcar con una X) | AB8: (18) Observaciones
I9: Agrícola | J9: Pecuario | K9: Forestal | L9: Hidrobiológico | M9: Hogar Rural | N9: Juventud y Niñez | O9: Asociatividad y Comercialización | P9: Otro
Q10: H | R10: M | S10: H | T10: M | U10: H | V10: M | Y10: Fotos | Z10: Listados | AA10: otros
A11: MOMOSTENANGO
U12: =Q12+S12 | V12: =R12+T12
U13: =Q13+S13 | V13: =R13+T13
U14: =Q14+S14 | V14: =R14+T14
U15: =Q15+S15 | V15: =R15+T15
U16: =Q16+S16 | V16: =R16+T16
U17: =Q17+S17 | V17: =R17+T17
U18: =Q18+S18 | V18: =R18+T18
U19: =Q19+S19 | V19: =R19+T19
U20: =Q20+S20 | V20: =R20+T20
U21: =Q21+S21 | V21: =R21+T21
A22: =COUNT(A12:A21) | B22: SUBTOTAL DE HORAS | E22: =SUM(E12:E21) | F22: SUBTOTAL DE PARTICIPANTES | I22: =COUNTIF(I12:I21,"X") | J22: =COUNTIF(J12:J21,"X") | K22: =COUNTIF(K12:K21,"X") | L22: =COUNTIF(L12:L21,"X") | M22: =COUNTIF(M12:M21,"X") | N22: =COUNTIF(N12:N21,"X") | O22: =COUNTIF(O12:O21,"X") | P22: =COUNTIF(P12:P21,"X") | Q22: =SUM(Q12:Q21) | R22: =SUM(R12:R21) | S22: =SUM(S12:S21) | T22: =SUM(T12:T21) | U22: =SUM(U12:U21) | V22: =SUM(V12:V21)
Q23: =Q22+R22 | S23: =S22+T22 | U23: =U22+V22
A24: SAN ANDRÉS XECUL
U25: =Q25+S25 | V25: =R25+T25
U26: =Q26+S26 | V26: =R26+T26
U27: =Q27+S27 | V27: =R27+T27
U28: =Q28+S28 | V28: =R28+T28
U29: =Q29+S29 | V29: =R29+T29
U30: =Q30+S30 | V30: =R30+T30
U31: =Q31+S31 | V31: =R31+T31
U32: =Q32+S32 | V32: =R32+T32
U33: =Q33+S33 | V33: =R33+T33
U34: =Q34+S34 | V34: =R34+T34
A35: =COUNT(A25:A34) | B35: SUBTOTAL DE HORAS | E35: =SUM(E25:E34) | F35: SUBTOTAL DE PARTICIPANTES | I35: =COUNTIF(I25:I34,"X") | J35: =COUNTIF(J25:J34,"X") | K35: =COUNTIF(K25:K34,"X") | L35: =COUNTIF(L25:L34,"X") | M35: =COUNTIF(M25:M34,"X") | N35: =COUNTIF(N25:N34,"X") | O35: =COUNTIF(O25:O34,"X") | P35: =COUNTIF(P25:P34,"X") | Q35: =SUM(Q25:Q34) | R35: =SUM(R25:R34) | S35: =SUM(S25:S34) | T35: =SUM(T25:T34) | U35: =SUM(U25:U34) | V35: =SUM(V25:V34)
Q36: =Q35+R35 | S36: =S35+T35 | U36: =U35+V35
A37: SAN BARTOLO
U38: =Q38+S38 | V38: =R38+T38
U39: =Q39+S39 | V39: =R39+T39
U40: =Q40+S40 | V40: =R40+T40
U41: =Q41+S41 | V41: =R41+T41
U42: =Q42+S42 | V42: =R42+T42
...

Sheet RESUMEN
C4: RESUMEN DE EVENTOS DE CAPACITACIÓN 2026
B6: No. | C6: NOMBRE DEL MUNICIPIO | D6: EVENTOS | E6: HORAS | F6: HOMBRES | G6: MUJERES | H6: SUB-TOTAL PARTICIPANTES
B7: 1 | C7: ='FORMATO DE CAPACITACIONES 2026'!A11 | D7: ='FORMATO DE CAPACITACIONES 2026'!A22 | E7: ='FORMATO DE CAPACITACIONES 2026'!E22 | F7: ='FORMATO DE CAPACITACIONES 2026'!U22 | G7: ='FORMATO DE CAPACITACIONES 2026'!V22 | H7: =SUM(F7:G7)
B8: 2 | C8: ='FORMATO DE CAPACITACIONES 2026'!A24 | D8: ='FORMATO DE CAPACITACIONES 2026'!A35 | E8: ='FORMATO DE CAPACITACIONES 2026'!E35 | F8: ='FORMATO DE CAPACITACIONES 2026'!U35 | G8: ='FORMATO DE CAPACITACIONES 2026'!V35 | H8: =SUM(F8:G8)
B9: 3 | C9: ='FORMATO DE CAPACITACIONES 2026'!A37 | D9: ='FORMATO DE CAPACITACIONES 2026'!A48 | E9: ='FORMATO DE CAPACITACIONES 2026'!E48 | F9: ='FORMATO DE CAPACITACIONES 2026'!U48 | G9: ='FORMATO DE CAPACITACIONES 2026'!V48 | H9: =SUM(F9:G9)
B10: 4 | C10: ='FORMATO DE CAPACITACIONES 2026'!A50 | D10: ='FORMATO DE CAPACITACIONES 2026'!A61 | E10: ='FORMATO DE CAPACITACIONES 2026'!E61 | F10: ='FORMATO DE CAPACITACIONES 2026'!U61 | G10: ='FORMATO DE CAPACITACIONES 2026'!V61 | H10: =SUM(F10:G10)
B11: 5 | C11: ='FORMATO DE CAPACITACIONES 2026'!A63 | D11: ='FORMATO DE CAPACITACIONES 2026'!A74 | E11: ='FORMATO DE CAPACITACIONES 2026'!E74 | F11: ='FORMATO DE CAPACITACIONES 2026'!U74 | G11: ='FORMATO DE CAPACITACIONES 2026'!V74 | H11: =SUM(F11:G11)
B12: 6 | C12: ='FORMATO DE CAPACITACIONES 2026'!A76 | D12: ='FORMATO DE CAPACITACIONES 2026'!A87 | E12: ='FORMATO DE CAPACITACIONES 2026'!E87 | F12: ='FORMATO DE CAPACITACIONES 2026'!U87 | G12: ='FORMATO DE CAPACITACIONES 2026'!V87 | H12: =SUM(F12:G12)
B13: 7 | C13: ='FORMATO DE CAPACITACIONES 2026'!A89 | D13: ='FORMATO DE CAPACITACIONES 2026'!A100 | E13: ='FORMATO DE CAPACITACIONES 2026'!E100 | F13: ='FORMATO DE CAPACITACIONES 2026'!U100 | G13: ='FORMATO DE CAPACITACIONES 2026'!V100 | H13: =SUM(F13:G13)
B14: 8 | C14: ='FORMATO DE CAPACITACIONES 2026'!A102 | D14: ='FORMATO DE CAPACITACIONES 2026'!A113 | E14: ='FORMATO DE CAPACITACIONES 2026'!E113 | F14: ='FORMATO DE CAPACITACIONES 2026'!U113 | G14: ='FORMATO DE CAPACITACIONES 2026'!V113 | H14: =SUM(F14:G14)
B15: 9 | C15: ='FORMATO DE CAPACITACIONES 2026'!A115 | D15: ='FORMATO DE CAPACITACIONES 2026'!A126 | E15: ='FORMATO DE CAPACITACIONES 2026'!E126 | F15: ='FORMATO DE CAPACITACIONES 2026'!U126 | G15: ='FORMATO DE CAPACITACIONES 2026'!V126 | H15: =SUM(F15:G15)
B16: TOTAL | D16: =SUM(D7:D15) | E16: =SUM(E7:E15) | F16: =SUM(F7:F15) | G16: =SUM(G7:G15) | H16: =SUM(H7:H15)
F17: =F16/H16*100% | G17: =G16/H16*100%
B19: RESUMEN DE INTERVENCIONES DE CAPACITACIÓN POR ACTIVIDAD | F19: PROMOTORES | G19: HOMBRES | H19: MUJERES
G20: ='FORMATO DE CAPACITACIONES 2026'!Q22+'FORMATO DE CAPACITACIONES 2026'!Q35+'FORMATO DE CAPACITACIONES 2026'!Q48+'FORMATO DE CAPACITACIONES 2026'!Q61+'FORMATO DE CAPACITACIONES 2026'!Q74+'FORMATO DE CAPACITACIONES 2026'!Q87+'FORMATO DE CAPACITACIONES 2026'!Q100+'FORMATO DE CAPACITACIONES 2026'!Q113+'FORMATO DE CAPACITACIONES 2026'!Q126 | H20: ='FORMATO DE CAPACITACIONES 2026'!R22+'FORMATO DE CAPACITACIONES 2026'!R35+'FORMATO DE CAPACITACIONES 2026'!R48+'FORMATO DE CAPACITACIONES 2026'!R61+'FORMATO DE CAPACITACIONES 2026'!R74+'FORMATO DE CAPACITACIONES 2026'!R87+'FORMATO DE CAPACITACIONES 2026'!R100+'FORMATO DE CAPACITACIONES 2026'!R113+'FORMATO DE CAPACITACIONES 2026'!R126
B21: No. | C21: Categoría de las capacitaciones | D21: EVENTOS
B22: 1 | C22: Agrícola | D22: ='FORMATO DE CAPACITACIONES 2026'!I22+'FORMATO DE CAPACITACIONES 2026'!I35+'FORMATO DE CAPACITACIONES 2026'!I48+'FORMATO DE CAPACITACIONES 2026'!I61+'FORMATO DE CAPACITACIONES 2026'!I74+'FORMATO DE CAPACITACIONES 2026'!I87+'FORMATO DE CAPACITACIONES 2026'!I100+'FORMATO DE CAPACITACIONES 2026'!I113+'FORMATO DE CAPACITACIONES 2026'!I126
B23: 2 | C23: Pecuario | D23: ='FORMATO DE CAPACITACIONES 2026'!J22+'FORMATO DE CAPACITACIONES 2026'!J35+'FORMATO DE CAPACITACIONES 2026'!J48+'FORMATO DE CAPACITACIONES 2026'!J61+'FORMATO DE CAPACITACIONES 2026'!J74+'FORMATO DE CAPACITACIONES 2026'!J87+'FORMATO DE CAPACITACIONES 2026'!J100+'FORMATO DE CAPACITACIONES 2026'!J113+'FORMATO DE CAPACITACIONES 2026'!J126
B24: 3 | C24: Forestal | D24: ='FORMATO DE CAPACITACIONES 2026'!K22+'FORMATO DE CAPACITACIONES 2026'!K35+'FORMATO DE CAPACITACIONES 2026'!K48+'FORMATO DE CAPACITACIONES 2026'!K61+'FORMATO DE CAPACITACIONES 2026'!K74+'FORMATO DE CAPACITACIONES 2026'!K87+'FORMATO DE CAPACITACIONES 2026'!K100+'FORMATO DE CAPACITACIONES 2026'!K113+'FORMATO DE CAPACITACIONES 2026'!K126
B25: 4 | C25: Hidrobiológico | D25: ='FORMATO DE CAPACITACIONES 2026'!L22+'FORMATO DE CAPACITACIONES 2026'!L35+'FORMATO DE CAPACITACIONES 2026'!L48+'FORMATO DE CAPACITACIONES 2026'!L61+'FORMATO DE CAPACITACIONES 2026'!L74+'FORMATO DE CAPACITACIONES 2026'!L87+'FORMATO DE CAPACITACIONES 2026'!L100+'FORMATO DE CAPACITACIONES 2026'!L113+'FORMATO DE CAPACITACIONES 2026'!L126
B26: 5 | C26: Hogar Rural | D26: ='FORMATO DE CAPACITACIONES 2026'!M22+'FORMATO DE CAPACITACIONES 2026'!M35+'FORMATO DE CAPACITACIONES 2026'!M48+'FORMATO DE CAPACITACIONES 2026'!M61+'FORMATO DE CAPACITACIONES 2026'!M74+'FORMATO DE CAPACITACIONES 2026'!M87+'FORMATO DE CAPACITACIONES 2026'!M100+'FORMATO DE CAPACITACIONES 2026'!M113+'FORMATO DE CAPACITACIONES 2026'!M126
B27: 6 | C27: Juventud y Niñez | D27: ='FORMATO DE CAPACITACIONES 2026'!N22+'FORMATO DE CAPACITACIONES 2026'!N35+'FORMATO DE CAPACITACIONES 2026'!N48+'FORMATO DE CAPACITACIONES 2026'!N61+'FORMATO DE CAPACITACIONES 2026'!N74+'FORMATO DE CAPACITACIONES 2026'!N87+'FORMATO DE CAPACITACIONES 2026'!N100+'FORMATO DE CAPACITACIONES 2026'!N113+'FORMATO DE CAPACITACIONES 2026'!N126
B28: 7 | C28: Asociatividad y comercialización | D28: ='FORMATO DE CAPACITACIONES 2026'!O22+'FORMATO DE CAPACITACIONES 2026'!O35+'FORMATO DE CAPACITACIONES 2026'!O48+'FORMATO DE CAPACITACIONES 2026'!O61+'FORMATO DE CAPACITACIONES 2026'!O74+'FORMATO DE CAPACITACIONES 2026'!O87+'FORMATO DE CAPACITACIONES 2026'!O100+'FORMATO DE CAPACITACIONES 2026'!O113+'FORMATO DE CAPACITACIONES 2026'!O126
B29: 8 | C29: Otro | D29: ='FORMATO DE CAPACITACIONES 2026'!P22+'FORMATO DE CAPACITACIONES 2026'!P35+'FORMATO DE CAPACITACIONES 2026'!P48+'FORMATO DE CAPACITACIONES 2026'!P61+'FORMATO DE CAPACITACIONES 2026'!P74+'FORMATO DE CAPACITACIONES 2026'!P87+'FORMATO DE CAPACITACIONES 2026'!P100+'FORMATO DE CAPACITACIONES 2026'!P113+'FORMATO DE CAPACITACIONES 2026'!P126
B30: TOTAL | D30: =SUM(D22:D29)

Sheet INDICACIONES DE LLENADO
A3: INDICACIONES PARA EL LLENADO DEL FORMATO DE INFORME DE CAPACITACIÓN 2026
A5: (1) MES: | B5: Nombre del mes al que corresponde el informe
A6: (2) SEDE DEPARTAMENTAL : | B6: Nombre de la Sede Departamental que corresponde el informe
A7: (3) No. | B7: Numero correlativo de la cantidad de eventos realizados durante el mes informado
A8: (4) Nombre del evento | B8: Nombre completo de la actividad (taller, curso, seminario etc.) ÚNICAMENTE REPORTAR EVENTOS DE CAPACITACIÓN, NO REUNIONES NI VISITAS
A9: (5) Fecha de realización | B9: Fecha en que se realizó el evento
A10: (6) Comunidad, Aldea/Municipio | B10: Nombre de la comunidad, aldea y municipio en el cual se desarrolló el evento
A11: (7) Duración del evento (Horas) | B11: Cantidad de horas de duración de la actividad planificada
A12: (8) Nombre del promotor | B12: Nombre del promotor de la comunidad
A13: (9) No. De teléfono | B13: Número de teléfono del promotor de la comunidad
A14: (10) Nombre del capacitador | B14: Nombre de la persona encargada de llevar a cabo la capacitación
A15: (11) Orientación de la capacitación | B15: Intervención a la que aporta la capacitación (Agrícola, pecuario, forestal, hidrobiológico, Hogar Rural u otro)
A16: (12) Número de Extensionistas | B16: Número de extensionistas participantes en el evento, hombres y mujeres
... A23: (19) Observaciones | B23: Cualquier otro dato que se considere importante o de relevancia respecto a la actividad informada.
A26: Es importante para todos y todas que no cambiemos el formato, eso permitirá uniformizar el traslado y recepción de información.
A27: La informacion deberá ser enviada en el transcurso de los primeros 5 días de cada mes subsiguiente.
A29: La información mensual deberá ser enviada a :
A30: Lic. Iván Asdrubald Guzmán | B30: ivanguzman07.ig@gmail.com | D30: Apoyo Profesional Formación y Capacitación | G30: 5430-2859
B31: contratista.ivan.guzman@maga.gob.gt
A32: Ing. Carlos Ernesto Rosales Betancourt | B32: contratista.carlos.rosales@maga.gob.gt | D32: Apoyo Profesional Formación y Capacitación | G32: 4647-8550
